Workbook

Sheet Landing Sheet
A1: YOUR COMPANY NAME | D1: Flowerama
R2: =AF9/7 -> 142.85714
AE5: 3000 | AF5: 1000 | AG5: 300 | AH5: 300 | AI5: 100 | AJ5: 480 | AK5: 83 | AL5: 1000
V6: KPI | AE6: 1 | AF6: Sunday | AG6: 15 | AH6: 10 | AI6: 20 | AJ6: 12 | AK6: 25 | AL6: 5
A7: Date | B7: Dayo Month | C7: Dayo Year | D7: Dayo Week # | E7: Dayo Week Name | F7: Weeko Year | G7: Month # | H7: Month Name | I7: Quarter | J7: Foot Traffic (customers per day) | K7: Spend per Customer | L7: Total Revenue | M7: Daily COGS | N7: COGS | O7: Gross Margin | P7: buy online | Q7: Stems discard | R7: Wages paied by day | S7: Online Orders | T7: Delvery Total rev | U7: Delevry orders | V7: Peps in door | W7: Online delevery | X7: Conversion Rate | Y7: Avg Delevry cost % | Z7: Delevery percentage | AA7: percent of wage per hr | AB7: Average Delevery value per Order | AC7: Dollar wasted oer stem discarded | AD7: online order % | AE7: Rent / Lease | AF7: Wages and Salaries | AG7: Insurance | AH7: Electric | AI7: Water | AJ7: Phone | AK7: Internet | AL7: Delivery | AM7: Total Expenses | AN7: Profit
A8: 44562 | B8: 1 | C8: 1 | D8: 7 | E8: Saturday | F8: 1 | G8: 1 | H8: January | I8: 1 | J8: 18.248423 | K8: 63.210073 | L8: =J8*K8 -> 1153.4842 | M8: 0.38876823 | N8: =L8*M8 -> 448.43799 | O8: =L8-N8 -> 705.04617 | P8: 43.748147 | Q8: 6.6793627 | R8: =IF(E8=$AF$6,$R$2/5,$R$2/11) -> 12.987013 | S8: 28.155118 | T8: =L8*0.7 -> 807.43891 | U8: =T8/J8 -> 44.247051 | V8: 26.334351 | W8: =P8/U8 -> 0.98872459 | X8: =J8/V8 -> 0.69295131 | Y8: =N8/T8 -> 0.55538318 | Z8: =J8/U8 -> 0.41242123 | AA8: =R8/L8 -> 0.011258944 | AB8: =T8/J8 -> 44.247051 | AC8: =Q8/K8 -> 0.10566928 | AD8: =P8/L8 -> 0.03792696 | AE8: =IF(B8=$AE$6,$AE$5, ) -> 3000 | AF8: =IF(E8=$AF$6,$AF$5,"") | AG8: =IF(B8=$AG$6,$AG$5,"") | AH8: =IF($B$8=AH6,AH5,"") | AI8: =IF($B8=$AI$6,$AI$5,"") | AJ8: =IF($B8=$AJ$6,$AJ$5,"") | AK8: =IF($B8=$AK$6,$AK$5,"") | AL8: =IF($B8=$AL$6,$AL$5,"") | AM8: =SUM(AE8:AL8) -> 3000 | AN8: =O8-AM8 -> -2294.9538
A9: 44563 | B9: 2 | C9: 2 | D9: 1 | E9: Sunday | F9: 1 | G9: 1 | H9: January | I9: 1 | J9: 5.6481892 | K9: 37.00637 | L9: =J9*K9 -> 209.01898 | M9: 0.21121235 | N9: =L9*M9 -> 44.14739 | O9: =L9-N9 -> 164.87159 | P9: 15.607485 | Q9: 7.0101524 | R9: =IF(E9=$AF$6,$R$2/5,$R$2/11) -> 28.571429 | S9: 13.589794 | T9: =L9*0.7 -> 146.31329 | U9: =T9/J9 -> 25.904459 | V9: 13.883588 | W9: =P9/U9 -> 0.60250188 | X9: =J9/V9 -> 0.40682489 | Y9: =N9/T9 -> 0.30173193 | Z9: =J9/U9 -> 0.21803926 | AA9: =R9/L9 -> 0.13669299 | AB9: =T9/J9 -> 25.904459 | AC9: =Q9/K9 -> 0.18943096 | AD9: =P9/L9 -> 0.074670182 | AE9: =IF(B9=$AE$6,$AE$5, "") | AF9: =IF(E9=$AF$6,$AF$5,"") -> 1000 | AG9: =IF(B9=$AG$6,$AG$5,"") | AH9: =IF(B9=$AH$6,$AH$5,"") | AI9: =IF($B9=$AI$6,$AI$5,"") | AJ9: =IF($B9=$AJ$6,$AJ$5,"") | AK9: =IF($B9=$AK$6,$AK$5,"") | AL9: =IF($B9=$AL$6,$AL$5,"") | AM9: =SUM(AE9:AL9) -> 1000 | AN9: =O9-AM9 -> -835.12841
A10: 44564 | B10: 3 | C10: 3 | D10: 2 | E10: Monday | F10: 1 | G10: 1 | H10: January | I10: 1 | J10: 10.949241 | K10: 8.9188617 | L10: =J10*K10 -> 97.654762 | M10: 0.50933335 | N10: =L10*M10 -> 49.738827 | O10: =L10-N10 -> 47.915935 | P10: 36.952446 | Q10: 7.7018362 | R10: =IF(E10=$AF$6,$R$2/5,$R$2/11) -> 12.987013 | S10: 30.385295 | T10: =L10*0.7 -> 68.358333 | U10: =T10/J10 -> 6.2432032 | V10: 25.259286 | W10: =P10/U10 -> 5.918828 | X10: =J10/V10 -> 0.43347387 | Y10: =N10/T10 -> 0.72761907 | Z10: =J10/U10 -> 1.7537857 | AA10: =R10/L10 -> 0.13298904 | AB10: =T10/J10 -> 6.2432032 | AC10: =Q10/K10 -> 0.86354475 | AD10: =P10/L10 -> 0.37839881 | AE10: =IF(B10=$AE$6,$AE$5, "") | AF10: =IF(E10=$AF$6,$AF$5,"") | AG10: =IF(B10=$AG$6,$AG$5,"") | AH10: =IF(B10=$AH$6,$AH$5,"") | AI10: =IF($B10=$AI$6,$AI$5,"") | AJ10: =IF($B10=$AJ$6,$AJ$5,"") | AK10: =IF($B10=$AK$6,$AK$5,"") | AL10: =IF($B10=$AL$6,$AL$5,"") | AM10: =SUM(AE10:AL10) -> 0 | AN10: =O10-AM10 -> 47.915935
A11: 44565 | B11: 4 | C11: 4 | D11: 3 | E11: Tuesday | F11: 1 | G11: 1 | H11: January | I11: 1 | J11: 12.174664 | K11: 27.250856 | L11: =J11*K11 -> 331.77002 | M11: 0.36085715 | N11: =L11*M11 -> 119.72158 | O11: =L11-N11 -> 212.04843 | P11: 26.314823 | Q11: 5.9731019 | R11: =IF(E11=$AF$6,$R$2/5,$R$2/11) -> 12.987013 | S11: 25.204278 | T11: =L11*0.7 -> 232.23901 | U11: =T11/J11 -> 19.075599 | V11: 35.670771 | W11: =P11/U11 -> 1.3795018 | X11: =J11/V11 -> 0.34130645 | Y11: =N11/T11 -> 0.51551022 | Z11: =J11/U11 -> 0.63823233 | AA11: =R11/L11 -> 0.039144625 | AB11: =T11/J11 -> 19.075599 | AC11: =Q11/K11 -> 0.21918952 | AD11: =P11/L11 -> 0.07931646 | AE11: =IF(B11=$AE$6,$AE$5, "") | AF11: =IF(E11=$AF$6,$AF$5,"") | AG11: =IF(B11=$AG$6,$AG$5,"") | AH11: =IF(B11=$AH$6,$AH$5,"") | AI11: =IF($B11=$AI$6,$AI$5,"") | AJ11: =IF($B11=$AJ$6,$AJ$5,"") | AK11: =IF($B11=$AK$6,$AK$5,"") | AL11: =IF($B11=$AL$6,$AL$5,"") | AM11: =SUM(AE11:AL11) -> 0 | AN11: =O11-AM11 -> 212.04843
A12: 44566 | B12: 5 | C12: 5 | D12: 4 | E12: Wednesday | F12: 1 | G12: 1 | H12: January | I12: 1 | J12: 7.8061021 | K12: 38.12985 | L12: =J12*K12 -> 297.64551 | M12: 0.34623885 | N12: =L12*M12 -> 103.05644 | O12: =L12-N12 -> 194.58907 | P12: 32.519419 | Q12: 1.4195718 | R12: =IF(E12=$AF$6,$R$2/5,$R$2/11) -> 12.987013 | S12: 27.172086 | T12: =L12*0.7 -> 208.35185 | U12: =T12/J12 -> 26.690895 | V12: 24.852601 | W12: =P12/U12 -> 1.2183712 | X12: =J12/V12 -> 0.31409598 | Y12: =N12/T12 -> 0.49462693 | Z12: =J12/U12 -> 0.29246311 | AA12: =R12/L12 -> 0.043632485 | AB12: =T12/J12 -> 26.690895 | AC12: =Q12/K12 -> 0.037229934 | AD12: =P12/L12 -> 0.10925553 | AE12: =IF(B12=$AE$6,$AE$5, "") | AF12: =IF(E12=$AF$6,$AF$5,"") | AG12: =IF(B12=$AG$6,$AG$5,"") | AH12: =IF(B12=$AH$6,$AH$5,"") | AI12: =IF($B12=$AI$6,$AI$5,"") | AJ12: =IF($B12=$AJ$6,$AJ$5,"") | AK12: =IF($B12=$AK$6,$AK$5,"") | AL12: =IF($B12=$AL$6,$AL$5,"") -> 1000 | AM12: =SUM(AE12:AL12) -> 1000 | AN12: =O12-AM12 -> -805.41093
A13: 44567 | B13: 6 | C13: 6 | D13: 5 | E13: Thursday | F13: 1 | G13: 1 | H13: January | I13: 1 | J13: 9.2683237 | K13: 29.780468 | L13: =J13*K13 -> 276.01501 | M13: 0.40558507 | N13: =L13*M13 -> 111.94757 | O13: =L13-N13 -> 164.06745 | P13: 38.666184 | Q13: 8.9853593 | R13: =IF(E13=$AF$6,$R$2/5,$R$2/11) -> 12.987013 | S13: 34.524216 | T13: =L13*0.7 -> 193.21051 | U13: =T13/J13 -> 20.846327 | V13: 34.428736 | W13: =P13/U13 -> 1.85482 | X13: =J13/V13 -> 0.26920314 | Y13: =N13/T13 -> 0.57940724 | Z13: =J13/U13 -> 0.44460223 | AA13: =R13/L13 -> 0.047051835 | AB13: =T13/J13 -> 20.846327 | AC13: =Q13/K13 -> 0.30171989 | AD13: =P13/L13 -> 0.14008725 | AE13: =IF(B13=$AE$6,$AE$5, "") | AF13: =IF(E13=$AF$6,$AF$5,"") | AG13: =IF(B13=$AG$6,$AG$5,"") | AH13: =IF(B13=$AH$6,$AH$5,"") | AI13: =IF($B13=$AI$6,$AI$5,"") | AJ13: =IF($B13=$AJ$6,$AJ$5,"") | AK13: =IF($B13=$AK$6,$AK$5,"") | AL13: =IF($B13=$AL$6,$AL$5,"") | AM13: =SUM(AE13:AL13) -> 0 | AN13: =O13-AM13 -> 164.06745
A14: 44568 | B14: 7 | C14: 7 | D14: 6 | E14: Friday | F14: 1 | G14: 1 | H14: January | I14: 1 | J14: 5.7375578 | K14: 43.485501 | L14: =J14*K14 -> 249.50058 | M14: 0.39389748 | N14: =L14*M14 -> 98.277649 | O14: =L14-N14 -> 151.22293 | P14: 29.232184 | Q14: 7.0897059 | R14: =IF(E14=$AF$6,$R$2/5,$R$2/11) -> 12.987013 | S14: 31.126457 | T14: =L14*0.7 -> 174.6504 | U14: =T14/J14 -> 30.439851 | V14: 35.188495 | W14: =P14/U14 -> 0.96032612 | X14: =J14/V14 -> 0.16305209 | Y14: =N14/T14 -> 0.56271069 | Z14: =J14/U14 -> 0.18848837 | AA14: =R14/L14 -> 0.052052036 | AB14: =T14/J14 -> 30.439851 | AC14: =Q14/K14 -> 0.16303609 | AD14: =P14/L14 -> 0.11716279 | AE14: =IF(B14=$AE$6,$AE$5, "") | AF14: =IF(E14=$AF$6,$AF$5,"") | AG14: =IF(B14=$AG$6,$AG$5,"") | AH14: =IF(B14=$AH$6,$AH$5,"") | AI14: =IF($B14=$AI$6,$AI$5,"") | AJ14: =IF($B14=$AJ$6,$AJ$5,"") | AK14: =IF($B14=$AK$6,$AK$5,"") | AL14: =IF($B14=$AL$6,$AL$5,"") | AM14: =SUM(AE14:AL14) -> 0 | AN14: =O14-AM14 -> 151.22293
A15: 44569 | B15: 8 | C15: 8 | D15: 7 | E15: Saturday | F15: 1 | G15: 1 | H15: January | I15: 1 | J15: 9.6976877 | K15: 30.347755 | L15: =J15*K15 -> 294.30305 | M15: 0.33384866 | N15: =L15*M15 -> 98.252679 | O15: =L15-N15 -> 196.05037 | P15: 23.267168 | Q15: 2.1453246 | R15: =IF(E15=$AF$6,$R$2/5,$R$2/11) -> 12.987013 | S15: 30.204552 | T15: =L15*0.7 -> 206.01213 | U15: =T15/J15 -> 21.243428 | V15: 28.435653 | W15: =P15/U15 -> 1.0952643 | X15: =J15/V15 -> 0.34103973 | Y15: =N15/T15 -> 0.47692666 | Z15: =J15/U15 -> 0.45650295 | AA15: =R15/L15 -> 0.044128027 | AB15: =T15/J15 -> 21.243428 | AC15: =Q15/K15 -> 0.070691378 | AD15: =P15/L15 -> 0.079058535 | AE15: =IF(B15=$AE$6,$AE$5, "") | AF15: =IF(E15=$AF$6,$AF$5,"") | AG15: =IF(B15=$AG$6,$AG$5,"") | AH15: =IF(B15=$AH$6,$AH$5,"") | AI15: =IF($B15=$AI$6,$AI$5,"") | AJ15: =IF($B15=$AJ$6,$AJ$5,"") | AK15: =IF($B15=$AK$6,$AK$5,"") | AL15: =IF($B15=$AL$6,$AL$5,"") | AM15: =SUM(AE15:AL15) -> 0 | AN15: =O15-AM15 -> 196.05037
A16: 44570 | B16: 9 | C16: 9 | D16: 1 | E16: Sunday | F16: 2 | G16: 1 | H16: January | I16: 1 | J16: 5.5871449 | K16: 21.60263 | L16: =J16*K16 -> 120.69702 | M16: 0.27132475 | N16: =L16*M16 -> 32.748089 | O16: =L16-N16 -> 87.948933 | P16: 16.590911 | Q16: 3.6238352 | R16: =IF(E16=$AF$6,$R$2/5,$R$2/11) -> 28.571429 | S16: 14.680302 | T16: =L16*0.7 -> 84.487915 | U16: =T16/J16 -> 15.121841 | V16: 12.701462 | W16: =P16/U16 -> 1.0971489 | X16: =J16/V16 -> 0.43988203 | Y16: =N16/T16 -> 0.38760678 | Z16: =J16/U16 -> 0.36947519 | AA16: =R16/L16 -> 0.23672025 | AB16: =T16/J16 -> 15.121841 | AC16: =Q16/K16 -> 0.16774973 | AD16: =P16/L16 -> 0.13745916 | AE16: =IF(B16=$AE$6,$AE$5, "") | AF16: =IF(E16=$AF$6,$AF$5,"") -> 1000 | AG16: =IF(B16=$AG$6,$AG$5,"") | AH16: =IF(B16=$AH$6,$AH$5,"") | AI16: =IF($B16=$AI$6,$AI$5,"") | AJ16: =IF($B16=$AJ$6,$AJ$5,"") | AK16: =IF($B16=$AK$6,$AK$5,"") | AL16: =IF($B16=$AL$6,$AL$5,"") | AM16: =SUM(AE16:AL16) -> 1000 | AN16: =O16-AM16 -> -912.05107
A17: 44571 | B17: 10 | C17: 10 | D17: 2 | E17: Monday | F17: 2 | G17: 1 | H17: January | I17: 1 | J17: 8.7214496 | K17: 50.462988 | L17: =J17*K17 -> 440.11041 | M17: 0.29690507 | N17: =L17*M17 -> 130.67101 | O17: =L17-N17 -> 309.4394 | P17: 37.40443 | Q17: 7.6271942 | R17: =IF(E17=$AF$6,$R$2/5,$R$2/11) -> 12.987013 | S17: 25.73566 | T17: =L17*0.7 -> 308.07729 | U17: =T17/J17 -> 35.324092 | V17: 34.111474 | W17: =P17/U17 -> 1.0588929 | X17: =J17/V17 -> 0.25567496 | Y17: =N17/T17 -> 0.4241501 | Z17: =J17/U17 -> 0.24689806 | AA17: =R17/L17 -> 0.029508534 | AB17: =T17/J17 -> 35.324092 | AC17: =Q17/K17 -> 0.15114432 | AD17: =P17/L17 -> 0.084988743 | AE17: =IF(B17=$AE$6,$AE$5, "") | AF17: =IF(E17=$AF$6,$AF$5,"") | AG17: =IF(B17=$AG$6,$AG$5,"") | AH17: =IF(B17=$AH$6,$AH$5,"") -> 300 | AI17: =IF($B17=$AI$6,$AI$5,"") | AJ17: =IF($B17=$AJ$6,$AJ$5,"") | AK17: =IF($B17=$AK$6,$AK$5,"") | AL17: =IF($B17=$AL$6,$AL$5,"") | AM17: =SUM(AE17:AL17) -> 300 | AN17: =O17-AM17 -> 9.4393969
A18: 44572 | B18: 11 | C18: 11 | D18: 3 | E18: Tuesday | F18: 2 | G18: 1 | H18: January | I18: 1 | J18: 18.144643 | K18: 43.016572 | L18: =J18*K18 -> 780.52036 | M18: 0.52230161 | N18: =L18*M18 -> 407.66703 | O18: =L18-N18 -> 372.85332 | P18: 46.794366 | Q18: 9.3260607 | R18: =IF(E18=$AF$6,$R$2/5,$R$2/11) -> 12.987013 | S18: 31.99161 | T18: =L18*0.7 -> 546.36425 | U18: =T18/J18 -> 30.1116 | V18: 30.81582 | W18: =P18/U18 -> 1.5540312 | X18: =J18/V18 -> 0.58880936 | Y18: =N18/T18 -> 0.74614515 | Z18: =J18/U18 -> 0.60257984 | AA18: =R18/L18 -> 0.016638916 | AB18: =T18/J18 -> 30.1116 | AC18: =Q18/K18 -> 0.21680158 | AD18: =P18/L18 -> 0.059952782 | AE18: =IF(B18=$AE$6,$AE$5, "") | AF18: =IF(E18=$AF$6,$AF$5,"") | AG18: =IF(B18=$AG$6,$AG$5,"") | AH18: =IF(B18=$AH$6,$AH$5,"") | AI18: =IF($B18=$AI$6,$AI$5,"") | AJ18: =IF($B18=$AJ$6,$AJ$5,"") | AK18: =IF($B18=$AK$6,$AK$5,"") | AL18: =IF($B18=$AL$6,$AL$5,"") | AM18: =SUM(AE18:AL18) -> 0 | AN18: =O18-AM18 -> 372.85332
A19: 44573 | B19: 12 | C19: 12 | D19: 4 | E19: Wednesday | F19: 2 | G19: 1 | H19: January | I19: 1 | J19: 2.6356184 | K19: 23.051269 | L19: =J19*K19 -> 60.754349 | M19: 0.52234832 | N19: =L19*M19 -> 31.734932 | O19: =L19-N19 -> 29.019417 | P19: 29.957514 | Q19: 3.9756458 | R19: =IF(E19=$AF$6,$R$2/5,$R$2/11) -> 12.987013 | S19: 28.772989 | T19: =L19*0.7 -> 42.528045 | U19: =T19/J19 -> 16.135889 | V19: 27.099146 | W19: =P19/U19 -> 1.8565766 | X19: =J19/V19 -> 0.097258354 | Y19: =N19/T19 -> 0.74621188 | Z19: =J19/U19 -> 0.1633389 | AA19: =R19/L19 -> 0.21376269 | AB19: =T19/J19 -> 16.135889 | AC19: =Q19/K19 -> 0.17246971 | AD19: =P19/L19 -> 0.4930925 | AE19: =IF(B19=$AE$6,$AE$5, "") | AF19: =IF(E19=$AF$6,$AF$5,"") | AG19: =IF(B19=$AG$6,$AG$5,"") | AH19: =IF(B19=$AH$6,$AH$5,"") | AI19: =IF($B19=$AI$6,$AI$5,"") | AJ19: =IF($B19=$AJ$6,$AJ$5,"") -> 480 | AK19: =IF($B19=$AK$6,$AK$5,"") | AL19: =IF($B19=$AL$6,$AL$5,"") | AM19: =SUM(AE19:AL19) -> 480 | AN19: =O19-AM19 -> -450.98058
A20: 44574 | B20: 13 | C20: 13 | D20: 5 | E20: Thursday | F20: 2 | G20: 1 | H20: January | I20: 1 | J20: 13.689948 | K20: 52.886584 | L20: =J20*K20 -> 724.0146 | M20: 0.45813765 | N20: =L20*M20 -> 331.69835 | O20: =L20-N20 -> 392.31625 | P20: 30.053337 | Q20: 9.9404558 | R20: =IF(E20=$AF$6,$R$2/5,$R$2/11) -> 12.987013 | S20: 25.193107 | T20: =L20*0.7 -> 506.81022 | U20: =T20/J20 -> 37.020609 | V20: 26.834492 | W20: =P20/U20 -> 0.81180018 | X20: =J20/V20 -> 0.51016239 | Y20: =N20/T20 -> 0.65448236 | Z20: =J20/U20 -> 0.36979263 | AA20: =R20/L20 -> 0.017937501 | AB20: =T20/J20 -> 37.020609 | AC20: =Q20/K20 -> 0.18795799 | AD20: =P20/L20 -> 0.041509297 | AE20: =IF(B20=$AE$6,$AE$5, "") | AF20: =IF(E20=$AF$6,$AF$5,"") | AG20: =IF(B20=$AG$6,$AG$5,"") | AH20: =IF(B20=$AH$6,$AH$5,"") | AI20: =IF($B20=$AI$6,$AI$5,"") | AJ20: =IF($B20=$AJ$6,$AJ$5,"") | AK20: =IF($B20=$AK$6,$AK$5,"") | AL20: =IF($B20=$AL$6,$AL$5,"") | AM20: =SUM(AE20:AL20) -> 0 | AN20: =O20-AM20 -> 392.31625
... A360: 44914 | B360: 19 | C360: 353 | D360: 2 | E360: Monday | F360: 51 | G360: 12 | H360: December | I360: 4 | J360: 6.8184141 | K360: 28.518699 | L360: =J360*K360 -> 194.4523 | M360: 0.48413577 | N360: =L360*M360 -> 94.141316 | O360: =L360-N360 -> 100.31099 | P360: 35.067245 | Q360: 22.482861 | R360: =IF(E360=$AF$6,$R$2/5,$R$2/11) -> 12.987013 | S360: 46.152846 | T360: =L360*0.7 -> 136.11661 | U360: =T360/J360 -> 19.96309 | V360: 45.832731 | W360: =P360/U360 -> 1.7566041 | X360: =J360/V360 -> 0.14876735 | Y360: =N360/T360 -> 0.69162253 | Z360: =J360/U360 -> 0.34155104 | AA360: =R360/L360 -> 0.066787653 | AB360: =T360/J360 -> 19.96309 | AC360: =Q360/K360 -> 0.78835504 | AD360: =P360/L360 -> 0.18033854 | AE360: =IF(B360=$AE$6,$AE$5, "") | AF360: =IF(E360=$AF$6,$AF$5,"") | AG360: =IF(B360=$AG$6,$AG$5,"") | AH360: =IF(B360=$AH$6,$AH$5,"") | AI360: =IF($B360=$AI$6,$AI$5,"") | AJ360: =IF($B360=$AJ$6,$AJ$5,"") | AK360: =IF($B360=$AK$6,$AK$5,"") | AL360: =IF($B360=$AL$6,$AL$5,"") | AM360: =SUM(AE360:AL360) -> 0 | AN360: =O360-AM360 -> 100.31099
A361: 44915 | B361: 20 | C361: 354 | D361: 3 | E361: Tuesday | F361: 51 | G361: 12 | H361: December | I361: 4 | J361: 34.729872 | K361: 87.633024 | L361: 2700 | M361: 0.38146445 | N361: =L361*M361 -> 1029.954 | O361: =L361-N361 -> 1670.046 | P361: 61.378809 | Q361: 9.6321764 | R361: =IF(E361=$AF$6,$R$2/5,$R$2/11) -> 12.987013 | S361: 37.333048 | T361: =L361*0.7 -> 1890 | U361: =T361/J361 -> 54.420011 | V361: 52.870811 | W361: =P361/U361 -> 1.1278721 | X361: =J361/V361 -> 0.65688177 | Y361: =N361/T361 -> 0.54494921 | Z361: =J361/U361 -> 0.63818201 | AA361: =R361/L361 -> 0.0048100048 | AB361: =T361/J361 -> 54.420011 | AC361: =Q361/K361 -> 0.10991491 | AD361: =P361/L361 -> 0.022732892 | AE361: =IF(B361=$AE$6,$AE$5, "") | AF361: =IF(E361=$AF$6,$AF$5,"") | AG361: =IF(B361=$AG$6,$AG$5,"") | AH361: =IF(B361=$AH$6,$AH$5,"") | AI361: =IF($B361=$AI$6,$AI$5,"") -> 100 | AJ361: =IF($B361=$AJ$6,$AJ$5,"") | AK361: =IF($B361=$AK$6,$AK$5,"") | AL361: =IF($B361=$AL$6,$AL$5,"") | AM361: =SUM(AE361:AL361) -> 100 | AN361: =O361-AM361 -> 1570.046
A362: 44916 | B362: 21 | C362: 355 | D362: 4 | E362: Wednesday | F362: 51 | G362: 12 | H362: December | I362: 4 | J362: 10.265542 | K362: 95.818001 | L362: =J362*K362 -> 983.6237 | M362: 0.71915437 | N362: =L362*M362 -> 707.37729 | O362: =L362-N362 -> 276.24641 | P362: 30.361883 | Q362: 24.584828 | R362: =IF(E362=$AF$6,$R$2/5,$R$2/11) -> 12.987013 | S362: 41.685307 | T362: =L362*0.7 -> 688.53659 | U362: =T362/J362 -> 67.072601 | V362: 38.255351 | W362: =P362/U362 -> 0.45267192 | X362: =J362/V362 -> 0.26834264 | Y362: =N362/T362 -> 1.0273634 | Z362: =J362/U362 -> 0.1530512 | AA362: =R362/L362 -> 0.013203233 | AB362: =T362/J362 -> 67.072601 | AC362: =Q362/K362 -> 0.25657838 | AD362: =P362/L362 -> 0.030867376 | AE362: =IF(B362=$AE$6,$AE$5, "") | AF362: =IF(E362=$AF$6,$AF$5,"") | AG362: =IF(B362=$AG$6,$AG$5,"") | AH362: =IF(B362=$AH$6,$AH$5,"") | AI362: =IF($B362=$AI$6,$AI$5,"") | AJ362: =IF($B362=$AJ$6,$AJ$5,"") | AK362: =IF($B362=$AK$6,$AK$5,"") | AL362: =IF($B362=$AL$6,$AL$5,"") | AM362: =SUM(AE362:AL362) -> 0 | AN362: =O362-AM362 -> 276.24641
A363: 44917 | B363: 22 | C363: 356 | D363: 5 | E363: Thursday | F363: 51 | G363: 12 | H363: December | I363: 4 | J363: 20.317871 | K363: 8.5887738 | L363: =J363*K363 -> 174.5056 | M363: 0.34541969 | N363: =L363*M363 -> 60.27767 | O363: =L363-N363 -> 114.22793 | P363: 52.821631 | Q363: 18.605359 | R363: =IF(E363=$AF$6,$R$2/5,$R$2/11) -> 12.987013 | S363: 43.516424 | T363: =L363*0.7 -> 122.15392 | U363: =T363/J363 -> 6.0121417 | V363: 42.098056 | W363: =P363/U363 -> 8.7858261 | X363: =J363/V363 -> 0.48263205 | Y363: =N363/T363 -> 0.4934567 | Z363: =J363/U363 -> 3.3794731 | AA363: =R363/L363 -> 0.074421756 | AB363: =T363/J363 -> 6.0121417 | AC363: =Q363/K363 -> 2.1662416 | AD363: =P363/L363 -> 0.30269305 | AE363: =IF(B363=$AE$6,$AE$5, "") | AF363: =IF(E363=$AF$6,$AF$5,"") | AG363: =IF(B363=$AG$6,$AG$5,"") | AH363: =IF(B363=$AH$6,$AH$5,"") | AI363: =IF($B363=$AI$6,$AI$5,"") | AJ363: =IF($B363=$AJ$6,$AJ$5,"") | AK363: =IF($B363=$AK$6,$AK$5,"") | AL363: =IF($B363=$AL$6,$AL$5,"") | AM363: =SUM(AE363:AL363) -> 0 | AN363: =O363-AM363 -> 114.22793
A364: 44918 | B364: 23 | C364: 357 | D364: 6 | E364: Friday | F364: 51 | G364: 12 | H364: December | I364: 4 | J364: 27.072355 | K364: 53.693965 | L364: =J364*K364 -> 1453.6221 | M364: 0.62520535 | N364: =L364*M364 -> 908.81233 | O364: =L364-N364 -> 544.80979 | P364: 56.296011 | Q364: 21.532837 | R364: =IF(E364=$AF$6,$R$2/5,$R$2/11) -> 12.987013 | S364: 35.255251 | T364: =L364*0.7 -> 1017.5355 | U364: =T364/J364 -> 37.585776 | V364: 42.97565 | W364: =P364/U364 -> 1.497801 | X364: =J364/V364 -> 0.62994638 | Y364: =N364/T364 -> 0.8931505 | Z364: =J364/U364 -> 0.72028194 | AA364: =R364/L364 -> 0.0089342429 | AB364: =T364/J364 -> 37.585776 | AC364: =Q364/K364 -> 0.401029 | AD364: =P364/L364 -> 0.038728092 | AE364: =IF(B364=$AE$6,$AE$5, "") | AF364: =IF(E364=$AF$6,$AF$5,"") | AG364: =IF(B364=$AG$6,$AG$5,"") | AH364: =IF(B364=$AH$6,$AH$5,"") | AI364: =IF($B364=$AI$6,$AI$5,"") | AJ364: =IF($B364=$AJ$6,$AJ$5,"") | AK364: =IF($B364=$AK$6,$AK$5,"") | AL364: =IF($B364=$AL$6,$AL$5,"") | AM364: =SUM(AE364:AL364) -> 0 | AN364: =O364-AM364 -> 544.80979
A365: 44919 | B365: 24 | C365: 358 | D365: 7 | E365: Saturday | F365: 51 | G365: 12 | H365: December | I365: 4 | J365: 23.923233 | K365: 85.222041 | L365: =J365*K365 -> 2038.7867 | M365: 0.54986695 | N365: =L365*M365 -> 1121.0614 | O365: =L365-N365 -> 917.72529 | P365: 42.834192 | Q365: 26.151715 | R365: =IF(E365=$AF$6,$R$2/5,$R$2/11) -> 12.987013 | S365: 41.956361 | T365: =L365*0.7 -> 1427.1507 | U365: =T365/J365 -> 59.655428 | V365: 39.370492 | W365: =P365/U365 -> 0.71802672 | X365: =J365/V365 -> 0.60764373 | Y365: =N365/T365 -> 0.78552421 | Z365: =J365/U365 -> 0.40102357 | AA365: =R365/L365 -> 0.0063699714 | AB365: =T365/J365 -> 59.655428 | AC365: =Q365/K365 -> 0.30686562 | AD365: =P365/L365 -> 0.021009648 | AE365: =IF(B365=$AE$6,$AE$5, "") | AF365: =IF(E365=$AF$6,$AF$5,"") | AG365: =IF(B365=$AG$6,$AG$5,"") | AH365: =IF(B365=$AH$6,$AH$5,"") | AI365: =IF($B365=$AI$6,$AI$5,"") | AJ365: =IF($B365=$AJ$6,$AJ$5,"") | AK365: =IF($B365=$AK$6,$AK$5,"") | AL365: =IF($B365=$AL$6,$AL$5,"") | AM365: =SUM(AE365:AL365) -> 0 | AN365: =O365-AM365 -> 917.72529
A366: 44920 | B366: 25 | C366: 359 | D366: 1 | E366: Sunday | F366: 52 | G366: 12 | H366: December | I366: 4 | J366: 1.5888531 | K366: 12.699583 | L366: =J366*K366 -> 20.177772 | M366: 0.29650658 | N366: =L366*M366 -> 5.9828422 | O366: =L366-N366 -> 14.19493 | P366: 15.206224 | Q366: 3.7851211 | R366: =IF(E366=$AF$6,$R$2/5,$R$2/11) -> 28.571429 | S366: 16.194881 | T366: =L366*0.7 -> 14.124441 | U366: =T366/J366 -> 8.8897084 | V366: 15.691891 | W366: =P366/U366 -> 1.7105425 | X366: =J366/V366 -> 0.10125313 | Y366: =N366/T366 -> 0.42358082 | Z366: =J366/U366 -> 0.17872949 | AA366: =R366/L366 -> 1.4159853 | AB366: =T366/J366 -> 8.8897084 | AC366: =Q366/K366 -> 0.29805081 | AD366: =P366/L366 -> 0.75361263 | AE366: =IF(B366=$AE$6,$AE$5, "") | AF366: =IF(E366=$AF$6,$AF$5,"") -> 1000 | AG366: =IF(B366=$AG$6,$AG$5,"") | AH366: =IF(B366=$AH$6,$AH$5,"") | AI366: =IF($B366=$AI$6,$AI$5,"") | AJ366: =IF($B366=$AJ$6,$AJ$5,"") | AK366: =IF($B366=$AK$6,$AK$5,"") -> 83 | AL366: =IF($B366=$AL$6,$AL$5,"") | AM366: =SUM(AE366:AL366) -> 1083 | AN366: =O366-AM366 -> -1068.8051
A367: 44921 | B367: 26 | C367: 360 | D367: 2 | E367: Monday | F367: 52 | G367: 12 | H367: December | I367: 4 | J367: 4.6741504 | K367: 111.60408 | L367: =J367*K367 -> 521.65425 | M367: 0.48601576 | N367: =L367*M367 -> 253.53219 | O367: =L367-N367 -> 268.12206 | P367: 44.340542 | Q367: 14.151808 | R367: =IF(E367=$AF$6,$R$2/5,$R$2/11) -> 12.987013 | S367: 39.521039 | T367: =L367*0.7 -> 365.15798 | U367: =T367/J367 -> 78.122855 | V367: 29.957688 | W367: =P367/U367 -> 0.56757452 | X367: =J367/V367 -> 0.15602507 | Y367: =N367/T367 -> 0.69430823 | Z367: =J367/U367 -> 0.059830769 | AA367: =R367/L367 -> 0.024895825 | AB367: =T367/J367 -> 78.122855 | AC367: =Q367/K367 -> 0.12680368 | AD367: =P367/L367 -> 0.084999867 | AE367: =IF(B367=$AE$6,$AE$5, "") | AF367: =IF(E367=$AF$6,$AF$5,"") | AG367: =IF(B367=$AG$6,$AG$5,"") | AH367: =IF(B367=$AH$6,$AH$5,"") | AI367: =IF($B367=$AI$6,$AI$5,"") | AJ367: =IF($B367=$AJ$6,$AJ$5,"") | AK367: =IF($B367=$AK$6,$AK$5,"") | AL367: =IF($B367=$AL$6,$AL$5,"") | AM367: =SUM(AE367:AL367) -> 0 | AN367: =O367-AM367 -> 268.12206
A368: 44922 | B368: 27 | C368: 361 | D368: 3 | E368: Tuesday | F368: 52 | G368: 12 | H368: December | I368: 4 | J368: 12.657227 | K368: 79.692877 | L368: =J368*K368 -> 1008.6909 | M368: 0.75585499 | N368: =L368*M368 -> 762.42402 | O368: =L368-N368 -> 246.26684 | P368: 42.809633 | Q368: 21.087758 | R368: =IF(E368=$AF$6,$R$2/5,$R$2/11) -> 12.987013 | S368: 34.115318 | T368: =L368*0.7 -> 706.0836 | U368: =T368/J368 -> 55.785014 | V368: 36.796045 | W368: =P368/U368 -> 0.76740382 | X368: =J368/V368 -> 0.34398336 | Y368: =N368/T368 -> 1.0797928 | Z368: =J368/U368 -> 0.22689297 | AA368: =R368/L368 -> 0.012875117 | AB368: =T368/J368 -> 55.785014 | AC368: =Q368/K368 -> 0.26461283 | AD368: =P368/L368 -> 0.042440786 | AE368: =IF(B368=$AE$6,$AE$5, "") | AF368: =IF(E368=$AF$6,$AF$5,"") | AG368: =IF(B368=$AG$6,$AG$5,"") | AH368: =IF(B368=$AH$6,$AH$5,"") | AI368: =IF($B368=$AI$6,$AI$5,"") | AJ368: =IF($B368=$AJ$6,$AJ$5,"") | AK368: =IF($B368=$AK$6,$AK$5,"") | AL368: =IF($B368=$AL$6,$AL$5,"") | AM368: =SUM(AE368:AL368) -> 0 | AN368: =O368-AM368 -> 246.26684
A369: 44923 | B369: 28 | C369: 362 | D369: 4 | E369: Wednesday | F369: 52 | G369: 12 | H369: December | I369: 4 | J369: 17.054586 | K369: 45.871309 | L369: =J369*K369 -> 782.3162 | M369: 0.83468092 | N369: =L369*M369 -> 652.98441 | O369: =L369-N369 -> 129.33179 | P369: 32.750516 | Q369: 16.653138 | R369: =IF(E369=$AF$6,$R$2/5,$R$2/11) -> 12.987013 | S369: 35.290841 | T369: =L369*0.7 -> 547.62134 | U369: =T369/J369 -> 32.109916 | V369: 38.493287 | W369: =P369/U369 -> 1.0199502 | X369: =J369/V369 -> 0.44305352 | Y369: =N369/T369 -> 1.1924013 | Z369: =J369/U369 -> 0.53113144 | AA369: =R369/L369 -> 0.016600721 | AB369: =T369/J369 -> 32.109916 | AC369: =Q369/K369 -> 0.36304039 | AD369: =P369/L369 -> 0.041863528 | AE369: =IF(B369=$AE$6,$AE$5, "") | AF369: =IF(E369=$AF$6,$AF$5,"") | AG369: =IF(B369=$AG$6,$AG$5,"") | AH369: =IF(B369=$AH$6,$AH$5,"") | AI369: =IF($B369=$AI$6,$AI$5,"") | AJ369: =IF($B369=$AJ$6,$AJ$5,"") | AK369: =IF($B369=$AK$6,$AK$5,"") | AL369: =IF($B369=$AL$6,$AL$5,"") | AM369: =SUM(AE369:AL369) -> 0 | AN369: =O369-AM369 -> 129.33179
A370: 44924 | B370: 29 | C370: 363 | D370: 5 | E370: Thursday | F370: 52 | G370: 12 | H370: December | I370: 4 | J370: 20.391537 | K370: 56.738478 | L370: =J370*K370 -> 1156.9848 | M370: 0.5123357 | N370: =L370*M370 -> 592.7646 | O370: =L370-N370 -> 564.22016 | P370: 38.522717 | Q370: 17.296552 | R370: =IF(E370=$AF$6,$R$2/5,$R$2/11) -> 12.987013 | S370: 40.762155 | T370: =L370*0.7 -> 809.88933 | U370: =T370/J370 -> 39.716934 | V370: 36.646902 | W370: =P370/U370 -> 0.96993179 | X370: =J370/V370 -> 0.55643276 | Y370: =N370/T370 -> 0.73190815 | Z370: =J370/U370 -> 0.51342172 | AA370: =R370/L370 -> 0.011224878 | AB370: =T370/J370 -> 39.716934 | AC370: =Q370/K370 -> 0.30484696 | AD370: =P370/L370 -> 0.033295786 | AE370: =IF(B370=$AE$6,$AE$5, "") | AF370: =IF(E370=$AF$6,$AF$5,"") | AG370: =IF(B370=$AG$6,$AG$5,"") | AH370: =IF(B370=$AH$6,$AH$5,"") | AI370: =IF($B370=$AI$6,$AI$5,"") | AJ370: =IF($B370=$AJ$6,$AJ$5,"") | AK370: =IF($B370=$AK$6,$AK$5,"") | AL370: =IF($B370=$AL$6,$AL$5,"") | AM370: =SUM(AE370:AL370) -> 0 | AN370: =O370-AM370 -> 564.22016
A371: 44925 | B371: 30 | C371: 364 | D371: 6 | E371: Friday | F371: 52 | G371: 12 | H371: December | I371: 4 | J371: 21.387381 | K371: 33.597033 | L371: =J371*K371 -> 718.55254 | M371: 0.65940319 | N371: =L371*M371 -> 473.81584 | O371: =L371-N371 -> 244.7367 | P371: 47.393266 | Q371: 11.196263 | R371: =IF(E371=$AF$6,$R$2/5,$R$2/11) -> 12.987013 | S371: 48.075287 | T371: =L371*0.7 -> 502.98678 | U371: =T371/J371 -> 23.517923 | V371: 46.816452 | W371: =P371/U371 -> 2.0151977 | X371: =J371/V371 -> 0.45683472 | Y371: =N371/T371 -> 0.94200456 | Z371: =J371/U371 -> 0.9094077 | AA371: =R371/L371 -> 0.018073853 | AB371: =T371/J371 -> 23.517923 | AC371: =Q371/K371 -> 0.33325155 | AD371: =P371/L371 -> 0.065956577 | AE371: =IF(B371=$AE$6,$AE$5, "") | AF371: =IF(E371=$AF$6,$AF$5,"") | AG371: =IF(B371=$AG$6,$AG$5,"") | AH371: =IF(B371=$AH$6,$AH$5,"") | AI371: =IF($B371=$AI$6,$AI$5,"") | AJ371: =IF($B371=$AJ$6,$AJ$5,"") | AK371: =IF($B371=$AK$6,$AK$5,"") | AL371: =IF($B371=$AL$6,$AL$5,"") | AM371: =SUM(AE371:AL371) -> 0 | AN371: =O371-AM371 -> 244.7367
A372: 44926 | B372: 31 | C372: 365 | D372: 7 | E372: Saturday | F372: 52 | G372: 12 | H372: December | I372: 4 | J372: 6.403807 | K372: 55.163928 | L372: =J372*K372 -> 353.25915 | M372: 0.73075665 | N372: =L372*M372 -> 258.14647 | O372: =L372-N372 -> 95.112676 | P372: 43.641932 | Q372: 10.292481 | R372: =IF(E372=$AF$6,$R$2/5,$R$2/11) -> 12.987013 | S372: 40.949616 | T372: =L372*0.7 -> 247.2814 | U372: =T372/J372 -> 38.61475 | V372: 38.734059 | W372: =P372/U372 -> 1.1301881 | X372: =J372/V372 -> 0.16532755 | Y372: =N372/T372 -> 1.0439381 | Z372: =J372/U372 -> 0.16583837 | AA372: =R372/L372 -> 0.036763416 | AB372: =T372/J372 -> 38.61475 | AC372: =Q372/K372 -> 0.18657992 | AD372: =P372/L372 -> 0.12354084 | AE372: =IF(B372=$AE$6,$AE$5, "") | AF372: =IF(E372=$AF$6,$AF$5,"") | AG372: =IF(B372=$AG$6,$AG$5,"") | AH372: =IF(B372=$AH$6,$AH$5,"") | AI372: =IF($B372=$AI$6,$AI$5,"") | AJ372: =IF($B372=$AJ$6,$AJ$5,"") | AK372: =IF($B372=$AK$6,$AK$5,"") | AL372: =IF($B372=$AL$6,$AL$5,"") | AM372: =SUM(AE372:AL372) -> 0 | AN372: =O372-AM372 -> 95.112676
A373: 44927 | B373: 1 | C373: 366 | D373: 1 | E373: Sunday | F373: 52 | G373: 1 | H373: January | I373: 4 | J373: 13.608697 | K373: 28.088597 | L373: =J373*K373 -> 382.24921 | M373: 0.17156509 | N373: =L373*M373 -> 65.58062 | O373: =L373-N373 -> 316.66859 | P373: 28.984362 | Q373: 5.6991993 | R373: =IF(E373=$AF$6,$R$2/5,$R$2/11) -> 28.571429 | S373: 15.912487 | T373: =L373*0.7 -> 267.57445 | U373: =T373/J373 -> 19.662018 | V373: 19.553897 | W373: =P373/U373 -> 1.4741296 | X373: =J373/V373 -> 0.69595831 | Y373: =N373/T373 -> 0.24509299 | Z373: =J373/U373 -> 0.69213126 | AA373: =R373/L373 -> 0.074745553 | AB373: =T373/J373 -> 19.662018 | AC373: =Q373/K373 -> 0.20290082 | AD373: =P373/L373 -> 0.075825825 | AE373: =IF(B373=$AE$6,$AE$5, "") -> 3000 | AF373: =IF(E373=$AF$6,$AF$5,"") -> 1000 | AG373: =IF(B373=$AG$6,$AG$5,"") | AH373: =IF(B373=$AH$6,$AH$5,"") | AI373: =IF($B373=$AI$6,$AI$5,"") | AJ373: =IF($B373=$AJ$6,$AJ$5,"") | AK373: =IF($B373=$AK$6,$AK$5,"") | AL373: =IF($B373=$AL$6,$AL$5,"") | AM373: =SUM(AE373:AL373) -> 4000 | AN373: =O373-AM373 -> -3683.3314

Sheet flatfeet
A1: Date | B1: Dayo Month | C1: Dayo Year | D1: Dayo Week # | E1: Dayo Week Name | F1: Weeko Year | G1: Month # | H1: Month Name | I1: Quarter | J1: Foot Traffic (customers per day) | K1: Spend per Customer | L1: Total Revenue | M1: Daily COGS | N1: COGS | O1: Gross Margin | P1: Online delevery | Q1: Conversion Rate | R1: Avg Delevry cost % | S1: Delevery percentage | T1: percent of wage per hr | U1: Average Delevery value per Order | V1: Dollar wasted oer stem discarded | W1: online order % | X1: Online order # | Y1: Delevery orders | Z1: In store | AA1: Rent / Lease | AB1: Wages and Salaries | AC1: Insurance | AD1: Electric | AE1: Water | AF1: Phone | AG1: Internet | AH1: Delivery | AI1: Total Expenses | AJ1: Profit | AK1: Order Method | AL1: Order amount
A2: 44562 | B2: 1 | C2: 1 | D2: 7 | E2: Saturday | F2: 1 | G2: 1 | H2: January | I2: 1 | J2: 18 | K2: 63 | L2: 1153 | M2: 0.39 | N2: 448 | O2: 705 | P2: 0.99 | Q2: 0.69 | R2: 0.56 | S2: 0.41 | T2: 0.01 | U2: 44 | V2: 0.11 | W2: 0.04 | X2: =L2*W2 -> 46.12 | Y2: =S2*L2 -> 472.73 | Z2: =L2-(X2+Y2) -> 634.15 | AA2: 3000 | AI2: 3000 | AJ2: -2295 | AK2: In Store
A3: 44563 | B3: 2 | C3: 2 | D3: 1 | E3: Sunday | F3: 1 | G3: 1 | H3: January | I3: 1 | J3: 6 | K3: 37 | L3: 209 | M3: 0.21 | N3: 44 | O3: 165 | P3: 0.6 | Q3: 0.41 | R3: 0.3 | S3: 0.22 | T3: 0.14 | U3: 26 | V3: 0.19 | W3: 0.07 | X3: =L3*W3 -> 14.63 | Y3: =S3*L3 -> 45.98 | Z3: =L3-(X3+Y3) -> 148.39 | AB3: 1000 | AI3: 1000 | AJ3: -835 | AK3: Delevry
A4: 44564 | B4: 3 | C4: 3 | D4: 2 | E4: Monday | F4: 1 | G4: 1 | H4: January | I4: 1 | J4: 11 | K4: 9 | L4: 98 | M4: 0.51 | N4: 50 | O4: 48 | P4: 5.92 | Q4: 0.43 | R4: 0.73 | S4: 1.75 | T4: 0.13 | U4: 6 | V4: 0.86 | W4: 0.38 | X4: =L4*W4 -> 37.24 | Y4: =S4*L4 -> 171.5 | Z4: =L4-(X4+Y4) -> -110.74 | AI4: 0 | AJ4: 48 | AK4: Online
A5: 44565 | B5: 4 | C5: 4 | D5: 3 | E5: Tuesday | F5: 1 | G5: 1 | H5: January | I5: 1 | J5: 12 | K5: 27 | L5: 332 | M5: 0.36 | N5: 120 | O5: 212 | P5: 1.38 | Q5: 0.34 | R5: 0.52 | S5: 0.64 | T5: 0.04 | U5: 19 | V5: 0.22 | W5: 0.08 | X5: =L5*W5 -> 26.56 | Y5: =S5*L5 -> 212.48 | Z5: =L5-(X5+Y5) -> 92.96 | AI5: 0 | AJ5: 212
A6: 44566 | B6: 5 | C6: 5 | D6: 4 | E6: Wednesday | F6: 1 | G6: 1 | H6: January | I6: 1 | J6: 8 | K6: 38 | L6: 298 | M6: 0.35 | N6: 103 | O6: 195 | P6: 1.22 | Q6: 0.31 | R6: 0.49 | S6: 0.29 | T6: 0.04 | U6: 27 | V6: 0.04 | W6: 0.11 | X6: =L6*W6 -> 32.78 | Y6: =S6*L6 -> 86.42 | Z6: =L6-(X6+Y6) -> 178.8 | AH6: 1000 | AI6: 1000 | AJ6: -805
A7: 44567 | B7: 6 | C7: 6 | D7: 5 | E7: Thursday | F7: 1 | G7: 1 | H7: January | I7: 1 | J7: 9 | K7: 30 | L7: 276 | M7: 0.41 | N7: 112 | O7: 164 | P7: 1.85 | Q7: 0.27 | R7: 0.58 | S7: 0.44 | T7: 0.05 | U7: 21 | V7: 0.3 | W7: 0.14 | X7: =L7*W7 -> 38.64 | Y7: =S7*L7 -> 121.44 | Z7: =L7-(X7+Y7) -> 115.92 | AI7: 0 | AJ7: 164
A8: 44568 | B8: 7 | C8: 7 | D8: 6 | E8: Friday | F8: 1 | G8: 1 | H8: January | I8: 1 | J8: 6 | K8: 43 | L8: 250 | M8: 0.39 | N8: 98 | O8: 151 | P8: 0.96 | Q8: 0.16 | R8: 0.56 | S8: 0.19 | T8: 0.05 | U8: 30 | V8: 0.16 | W8: 0.12 | X8: =L8*W8 -> 30 | Y8: =S8*L8 -> 47.5 | Z8: =L8-(X8+Y8) -> 172.5 | AI8: 0 | AJ8: 151
A9: 44569 | B9: 8 | C9: 8 | D9: 7 | E9: Saturday | F9: 1 | G9: 1 | H9: January | I9: 1 | J9: 10 | K9: 30 | L9: 294 | M9: 0.33 | N9: 98 | O9: 196 | P9: 1.1 | Q9: 0.34 | R9: 0.48 | S9: 0.46 | T9: 0.04 | U9: 21 | V9: 0.07 | W9: 0.08 | X9: =L9*W9 -> 23.52 | Y9: =S9*L9 -> 135.24 | Z9: =L9-(X9+Y9) -> 135.24 | AI9: 0 | AJ9: 196
A10: 44570 | B10: 9 | C10: 9 | D10: 1 | E10: Sunday | F10: 2 | G10: 1 | H10: January | I10: 1 | J10: 6 | K10: 22 | L10: 121 | M10: 0.27 | N10: 33 | O10: 88 | P10: 1.1 | Q10: 0.44 | R10: 0.39 | S10: 0.37 | T10: 0.24 | U10: 15 | V10: 0.17 | W10: 0.14 | X10: =L10*W10 -> 16.94 | Y10: =S10*L10 -> 44.77 | Z10: =L10-(X10+Y10) -> 59.29 | AB10: 1000 | AI10: 1000 | AJ10: -912
A11: 44571 | B11: 10 | C11: 10 | D11: 2 | E11: Monday | F11: 2 | G11: 1 | H11: January | I11: 1 | J11: 9 | K11: 50 | L11: 440 | M11: 0.3 | N11: 131 | O11: 309 | P11: 1.06 | Q11: 0.26 | R11: 0.42 | S11: 0.25 | T11: 0.03 | U11: 35 | V11: 0.15 | W11: 0.08 | X11: =L11*W11 -> 35.2 | Y11: =S11*L11 -> 110 | Z11: =L11-(X11+Y11) -> 294.8 | AD11: 300 | AI11: 300 | AJ11: 9
A12: 44572 | B12: 11 | C12: 11 | D12: 3 | E12: Tuesday | F12: 2 | G12: 1 | H12: January | I12: 1 | J12: 18 | K12: 43 | L12: 781 | M12: 0.52 | N12: 408 | O12: 373 | P12: 1.55 | Q12: 0.59 | R12: 0.75 | S12: 0.6 | T12: 0.02 | U12: 30 | V12: 0.22 | W12: 0.06 | X12: =L12*W12 -> 46.86 | Y12: =S12*L12 -> 468.6 | Z12: =L12-(X12+Y12) -> 265.54 | AI12: 0 | AJ12: 373
A13: 44573 | B13: 12 | C13: 12 | D13: 4 | E13: Wednesday | F13: 2 | G13: 1 | H13: January | I13: 1 | J13: 3 | K13: 23 | L13: 61 | M13: 0.52 | N13: 32 | O13: 29 | P13: 1.86 | Q13: 0.1 | R13: 0.75 | S13: 0.16 | T13: 0.21 | U13: 16 | V13: 0.17 | W13: 0.49 | X13: =L13*W13 -> 29.89 | Y13: =S13*L13 -> 9.76 | Z13: =L13-(X13+Y13) -> 21.35 | AF13: 480 | AI13: 480 | AJ13: -451
A14: 44574 | B14: 13 | C14: 13 | D14: 5 | E14: Thursday | F14: 2 | G14: 1 | H14: January | I14: 1 | J14: 14 | K14: 53 | L14: 724 | M14: 0.46 | N14: 332 | O14: 392 | P14: 0.81 | Q14: 0.51 | R14: 0.65 | S14: 0.37 | T14: 0.02 | U14: 37 | V14: 0.19 | W14: 0.04 | X14: =L14*W14 -> 28.96 | Y14: =S14*L14 -> 267.88 | Z14: =L14-(X14+Y14) -> 427.16 | AI14: 0 | AJ14: 392
A15: 44575 | B15: 14 | C15: 14 | D15: 6 | E15: Friday | F15: 2 | G15: 1 | H15: January | I15: 1 | J15: 11 | K15: 38 | L15: 427 | M15: 0.52 | N15: 221 | O15: 206 | P15: 1.75 | Q15: 0.43 | R15: 0.74 | S15: 0.42 | T15: 0.03 | U15: 27 | V15: 0.36 | W15: 0.11 | X15: =L15*W15 -> 46.97 | Y15: =S15*L15 -> 179.34 | Z15: =L15-(X15+Y15) -> 200.69 | AI15: 0 | AJ15: 206
A16: 44576 | B16: 15 | C16: 15 | D16: 7 | E16: Saturday | F16: 2 | G16: 1 | H16: January | I16: 1 | J16: 13 | K16: 50 | L16: 643 | M16: 0.32 | N16: 204 | O16: 439 | P16: 0.92 | Q16: 0.58 | R16: 0.45 | S16: 0.36 | T16: 0.02 | U16: 35 | V16: 0.25 | W16: 0.05 | X16: =L16*W16 -> 32.15 | Y16: =S16*L16 -> 231.48 | Z16: =L16-(X16+Y16) -> 379.37 | AC16: 300 | AI16: 300 | AJ16: 139
A17: 44577 | B17: 16 | C17: 16 | D17: 1 | E17: Sunday | F17: 3 | G17: 1 | H17: January | I17: 1 | J17: 4 | K17: 7 | L17: 28 | M17: 0.12 | N17: 3 | O17: 24 | P17: 4.54 | Q17: 0.23 | R17: 0.18 | S17: 0.9 | T17: 1.03 | U17: 5 | V17: 0.46 | W17: 0.76 | X17: =L17*W17 -> 21.28 | Y17: =S17*L17 -> 25.2 | Z17: =L17-(X17+Y17) -> -18.48 | AB17: 1000 | AI17: 1000 | AJ17: -976
A18: 44578 | B18: 17 | C18: 17 | D18: 2 | E18: Monday | F18: 3 | G18: 1 | H18: January | I18: 1 | J18: 9 | K18: 19 | L18: 170 | M18: 0.36 | N18: 62 | O18: 108 | P18: 3.02 | Q18: 0.25 | R18: 0.52 | S18: 0.67 | T18: 0.08 | U18: 13 | V18: 0.35 | W18: 0.24 | X18: =L18*W18 -> 40.8 | Y18: =S18*L18 -> 113.9 | Z18: =L18-(X18+Y18) -> 15.3 | AI18: 0 | AJ18: 108
A19: 44579 | B19: 18 | C19: 18 | D19: 3 | E19: Tuesday | F19: 3 | G19: 1 | H19: January | I19: 1 | J19: 11 | K19: 41 | L19: 452 | M19: 0.37 | N19: 169 | O19: 284 | P19: 0.38 | Q19: 0.36 | R19: 0.53 | S19: 0.38 | T19: 0.03 | U19: 29 | V19: 0.2 | W19: 0.02 | X19: =L19*W19 -> 9.04 | Y19: =S19*L19 -> 171.76 | Z19: =L19-(X19+Y19) -> 271.2 | AI19: 0 | AJ19: 284
A20: 44580 | B20: 19 | C20: 19 | D20: 4 | E20: Wednesday | F20: 3 | G20: 1 | H20: January | I20: 1 | J20: 8 | K20: 28 | L20: 232 | M20: 0.27 | N20: 62 | O20: 170 | P20: 2.12 | Q20: 0.31 | R20: 0.38 | S20: 0.42 | T20: 0.06 | U20: 20 | V20: 0.23 | W20: 0.18 | X20: =L20*W20 -> 41.76 | Y20: =S20*L20 -> 97.44 | Z20: =L20-(X20+Y20) -> 92.8 | AI20: 0 | AJ20: 170
A21: 44581 | B21: 20 | C21: 20 | D21: 5 | E21: Thursday | F21: 3 | G21: 1 | H21: January | I21: 1 | J21: 15 | K21: 56 | L21: 822 | M21: 0.32 | N21: 266 | O21: 556 | P21: 1.15 | Q21: 0.51 | R21: 0.46 | S21: 0.37 | T21: 0.02 | U21: 39 | V21: 0.15 | W21: 0.06 | X21: =L21*W21 -> 49.32 | Y21: =S21*L21 -> 304.14 | Z21: =L21-(X21+Y21) -> 468.54 | AE21: 100 | AI21: 100 | AJ21: 456
A22: 44582 | B22: 21 | C22: 21 | D22: 6 | E22: Friday | F22: 3 | G22: 1 | H22: January | I22: 1 | J22: 16 | K22: 72 | L22: 1169 | M22: 0.31 | N22: 362 | O22: 807 | P22: 0.36 | Q22: 0.62 | R22: 0.44 | S22: 0.33 | T22: 0.01 | U22: 50 | V22: 0.1 | W22: 0.02 | X22: =L22*W22 -> 23.38 | Y22: =S22*L22 -> 385.77 | Z22: =L22-(X22+Y22) -> 759.85 | AI22: 0 | AJ22: 807
A23: 44583 | B23: 22 | C23: 22 | D23: 7 | E23: Saturday | F23: 3 | G23: 1 | H23: January | I23: 1 | J23: 14 | K23: 50 | L23: 697 | M23: 0.51 | N23: 356 | O23: 340 | P23: 0.97 | Q23: 0.54 | R23: 0.73 | S23: 0.4 | T23: 0.02 | U23: 35 | V23: 0.2 | W23: 0.05 | X23: =L23*W23 -> 34.85 | Y23: =S23*L23 -> 278.8 | Z23: =L23-(X23+Y23) -> 383.35 | AI23: 0 | AJ23: 340
A24: 44584 | B24: 23 | C24: 23 | D24: 1 | E24: Sunday | F24: 4 | G24: 1 | H24: January | I24: 1 | J24: 8 | K24: 29 | L24: 229 | M24: 0.19 | N24: 45 | O24: 185 | P24: 1.51 | Q24: 0.41 | R24: 0.28 | S24: 0.39 | T24: 0.12 | U24: 20 | V24: 0.1 | W24: 0.13 | X24: =L24*W24 -> 29.77 | Y24: =S24*L24 -> 89.31 | Z24: =L24-(X24+Y24) -> 109.92 | AB24: 1000 | AI24: 1000 | AJ24: -815
A25: 44585 | B25: 24 | C25: 24 | D25: 2 | E25: Monday | F25: 4 | G25: 1 | H25: January | I25: 1 | J25: 11 | K25: 49 | L25: 555 | M25: 0.3 | N25: 166 | O25: 389 | P25: 2.13 | Q25: 0.19 | R25: 0.43 | S25: 0.33 | T25: 0.02 | U25: 34 | V25: 0.29 | W25: 0.13 | X25: =L25*W25 -> 72.15 | Y25: =S25*L25 -> 183.15 | Z25: =L25-(X25+Y25) -> 299.7 | AI25: 0 | AJ25: 389
A26: 44586 | B26: 25 | C26: 25 | D26: 3 | E26: Tuesday | F26: 4 | G26: 1 | H26: January | I26: 1 | J26: 13 | K26: 118 | L26: 1563 | M26: 0.15 | N26: 239 | O26: 1324 | P26: 0.54 | Q26: 0.3 | R26: 0.22 | S26: 0.16 | T26: 0.01 | U26: 82 | V26: 0.08 | W26: 0.03 | X26: =L26*W26 -> 46.89 | Y26: =S26*L26 -> 250.08 | Z26: =L26-(X26+Y26) -> 1266.03 | AG26: 83 | AI26: 83 | AJ26: 1241
A27: 44587 | B27: 26 | C27: 26 | D27: 4 | E27: Wednesday | F27: 4 | G27: 1 | H27: January | I27: 1 | J27: 16 | K27: 70 | L27: 1091 | M27: 0.55 | N27: 598 | O27: 493 | P27: 1.03 | Q27: 0.35 | R27: 0.78 | S27: 0.32 | T27: 0.01 | U27: 49 | V27: 0.21 | W27: 0.05 | X27: =L27*W27 -> 54.55 | Y27: =S27*L27 -> 349.12 | Z27: =L27-(X27+Y27) -> 687.33 | AI27: 0 | AJ27: 493
A28: 44588 | B28: 27 | C28: 27 | D28: 5 | E28: Thursday | F28: 4 | G28: 1 | H28: January | I28: 1 | J28: 8 | K28: 50 | L28: 411 | M28: 0.65 | N28: 268 | O28: 143 | P28: 1.09 | Q28: 0.15 | R28: 0.93 | S28: 0.24 | T28: 0.03 | U28: 35 | V28: 0.31 | W28: 0.09 | X28: =L28*W28 -> 36.99 | Y28: =S28*L28 -> 98.64 | Z28: =L28-(X28+Y28) -> 275.37 | AI28: 0 | AJ28: 143
A29: 44589 | B29: 28 | C29: 28 | D29: 6 | E29: Friday | F29: 4 | G29: 1 | H29: January | I29: 1 | J29: 17 | K29: 51 | L29: 841 | M29: 0.48 | N29: 407 | O29: 434 | P29: 1.96 | Q29: 0.32 | R29: 0.69 | S29: 0.46 | T29: 0.02 | U29: 36 | V29: 0.31 | W29: 0.08 | X29: =L29*W29 -> 67.28 | Y29: =S29*L29 -> 386.86 | Z29: =L29-(X29+Y29) -> 386.86 | AI29: 0 | AJ29: 434
A30: 44590 | B30: 29 | C30: 29 | D30: 7 | E30: Saturday | F30: 4 | G30: 1 | H30: January | I30: 1 | J30: 11 | K30: 94 | L30: 1034 | M30: 0.25 | N30: 258 | O30: 776 | P30: 0.74 | Q30: 0.19 | R30: 0.36 | S30: 0.17 | T30: 0.01 | U30: 66 | V30: 0.16 | W30: 0.05 | X30: =L30*W30 -> 51.7 | Y30: =S30*L30 -> 175.78 | Z30: =L30-(X30+Y30) -> 806.52 | AI30: 0 | AJ30: 776
A31: 44591 | B31: 30 | C31: 30 | D31: 1 | E31: Sunday | F31: 5 | G31: 1 | H31: January | I31: 1 | J31: 7 | K31: 25 | L31: 184 | M31: 0.23 | N31: 43 | O31: 141 | P31: 2.07 | Q31: 0.25 | R31: 0.33 | S31: 0.42 | T31: 0.15 | U31: 18 | V31: 0.15 | W31: 0.2 | X31: =L31*W31 -> 36.8 | Y31: =S31*L31 -> 77.28 | Z31: =L31-(X31+Y31) -> 69.92 | AB31: 1000 | AI31: 1000 | AJ31: -859
A32: 44592 | B32: 31 | C32: 31 | D32: 2 | E32: Monday | F32: 5 | G32: 1 | H32: January | I32: 1 | J32: 9 | K32: 32 | L32: 282 | M32: 0.52 | N32: 147 | O32: 135 | P32: 3.18 | Q32: 0.13 | R32: 0.75 | S32: 0.39 | T32: 0.05 | U32: 23 | V32: 0.24 | W32: 0.25 | X32: =L32*W32 -> 70.5 | Y32: =S32*L32 -> 109.98 | Z32: =L32-(X32+Y32) -> 101.52 | AI32: 0 | AJ32: 135
A33: 44593 | B33: 1 | C33: 32 | D33: 3 | E33: Tuesday | F33: 5 | G33: 2 | H33: February | I33: 1 | J33: 15 | K33: 51 | L33: 740 | M33: 0.44 | N33: 328 | O33: 412 | P33: 1.74 | Q33: 0.24 | R33: 0.63 | S33: 0.41 | T33: 0.02 | U33: 36 | V33: 0.27 | W33: 0.08 | X33: =L33*W33 -> 59.2 | Y33: =S33*L33 -> 303.4 | Z33: =L33-(X33+Y33) -> 377.4 | AA33: 3000 | AI33: 3000 | AJ33: -2588
A34: 44594 | B34: 2 | C34: 33 | D34: 4 | E34: Wednesday | F34: 5 | G34: 2 | H34: February | I34: 1 | J34: 28 | K34: 61 | L34: 1684 | M34: 0.54 | N34: 908 | O34: 776 | P34: 1.69 | Q34: 0.55 | R34: 0.77 | S34: 0.65 | T34: 0.01 | U34: 43 | V34: 0.46 | W34: 0.04 | X34: =L34*W34 -> 67.36 | Y34: =S34*L34 -> 1094.6 | Z34: =L34-(X34+Y34) -> 522.04 | AI34: 0 | AJ34: 776
A35: 44595 | B35: 3 | C35: 34 | D35: 5 | E35: Thursday | F35: 5 | G35: 2 | H35: February | I35: 1 | J35: 12 | K35: 32 | L35: 387 | M35: 0.38 | N35: 147 | O35: 240 | P35: 3.85 | Q35: 0.31 | R35: 0.54 | S35: 0.55 | T35: 0.03 | U35: 22 | V35: 0.37 | W35: 0.22 | X35: =L35*W35 -> 85.14 | Y35: =S35*L35 -> 212.85 | Z35: =L35-(X35+Y35) -> 89.01 | AI35: 0 | AJ35: 240
A36: 44596 | B36: 4 | C36: 35 | D36: 6 | E36: Friday | F36: 5 | G36: 2 | H36: February | I36: 1 | J36: 11 | K36: 75 | L36: 824 | M36: 0.34 | N36: 283 | O36: 541 | P36: 1.3 | Q36: 0.18 | R36: 0.49 | S36: 0.21 | T36: 0.02 | U36: 52 | V36: 0.21 | W36: 0.08 | X36: =L36*W36 -> 65.92 | Y36: =S36*L36 -> 173.04 | Z36: =L36-(X36+Y36) -> 585.04 | AI36: 0 | AJ36: 541
A37: 44597 | B37: 5 | C37: 36 | D37: 7 | E37: Saturday | F37: 5 | G37: 2 | H37: February | I37: 1 | J37: 5 | K37: 30 | L37: 143 | M37: 0.32 | N37: 46 | O37: 97 | P37: 3.85 | Q37: 0.08 | R37: 0.46 | S37: 0.23 | T37: 0.09 | U37: 21 | V37: 0.74 | W37: 0.56 | X37: =L37*W37 -> 80.08 | Y37: =S37*L37 -> 32.89 | Z37: =L37-(X37+Y37) -> 30.03 | AH37: 1000 | AI37: 1000 | AJ37: -903
A38: 44598 | B38: 6 | C38: 37 | D38: 1 | E38: Sunday | F38: 6 | G38: 2 | H38: February | I38: 1 | J38: 13 | K38: 41 | L38: 536 | M38: 0.26 | N38: 139 | O38: 398 | P38: 0.74 | Q38: 0.64 | R38: 0.37 | S38: 0.46 | T38: 0.05 | U38: 28 | V38: 0.04 | W38: 0.04 | X38: =L38*W38 -> 21.44 | Y38: =S38*L38 -> 246.56 | Z38: =L38-(X38+Y38) -> 268 | AB38: 1000 | AI38: 1000 | AJ38: -602
A39: 44599 | B39: 7 | C39: 38 | D39: 2 | E39: Monday | F39: 6 | G39: 2 | H39: February | I39: 1 | J39: 11 | K39: 56 | L39: 616 | M39: 0.82 | N39: 503 | O39: 113 | P39: 1.09 | Q39: 0.16 | R39: 1.17 | S39: 0.28 | T39: 0.02 | U39: 39 | V39: 0.09 | W39: 0.07 | X39: =L39*W39 -> 43.12 | Y39: =S39*L39 -> 172.48 | Z39: =L39-(X39+Y39) -> 400.4 | AI39: 0 | AJ39: 113
A40: 44600 | B40: 8 | C40: 39 | D40: 3 | E40: Tuesday | F40: 6 | G40: 2 | H40: February | I40: 1 | J40: 12 | K40: 143 | L40: 1721 | M40: 0.63 | N40: 1092 | O40: 629 | P40: 0.83 | Q40: 0.18 | R40: 0.91 | S40: 0.12 | T40: 0.01 | U40: 100 | V40: 0.08 | W40: 0.05 | X40: =L40*W40 -> 86.05 | Y40: =S40*L40 -> 206.52 | Z40: =L40-(X40+Y40) -> 1428.43 | AI40: 0 | AJ40: 629
...

Sheet Chance
A1: YOUR COMPANY NAME | D1: Flowerama
S2: =AG9/7 -> 142.85714
AG4: =AG5+200 -> 1200
AF5: 3000 | AG5: 1000 | AH5: 300 | AI5: 300 | AJ5: 100 | AK5: 480 | AL5: 83 | AM5: 1000
W6: KPI | AF6: 1 | AG6: Sunday | AH6: 15 | AI6: 10 | AJ6: 20 | AK6: 12 | AL6: 25 | AM6: 5
A7: Date | B7: Dayo Month | C7: Dayo Year | D7: Dayo Week # | E7: Dayo Week Name | F7: Weeko Year | G7: Month # | H7: Month Name | I7: Quarter | J7: Foot Traffic (customers per day) | K7: Chance Foot Traffic | L7: Spend per Customer | M7: Total Revenue | N7: Daily COGS | O7: COGS | P7: Gross Margin | Q7: buy online | R7: Stems discard | S7: Wages paied by day | T7: Online Orders | U7: Delvery Total rev | V7: Delevry orders | W7: Peps in door | X7: Online delevery | Y7: Conversion Rate | Z7: Avg Delevry cost % | AA7: Delevery percentage | AB7: percent of wage per hr | AC7: Average Delevery value per Order | AD7: Dollar wasted oer stem discarded | AE7: online order % | AF7: Rent / Lease | AG7: Wages and Salaries | AH7: Insurance | AI7: Electric | AJ7: Water | AK7: Phone | AL7: Internet | AM7: Delivery | AN7: Total Expenses | AO7: Profit
A8: 44562 | B8: 1 | C8: 1 | D8: 7 | E8: Saturday | F8: 1 | G8: 1 | H8: January | I8: 1 | J8: 18.248423 | K8: =J8 -> 18.248423 | L8: 63.210073 | M8: =K8*L8 -> 1153.4842 | N8: 0.38876823 | O8: =M8*N8 -> 448.43799 | P8: =M8-O8 -> 705.04617 | Q8: 43.748147 | R8: 6.6793627 | S8: =IF(E8=$AG$6,$S$2/5,$S$2/11) -> 12.987013 | T8: 28.155118 | U8: =M8*0.7 -> 807.43891 | V8: =U8/K8 -> 44.247051 | W8: 26.334351 | X8: =Q8/V8 -> 0.98872459 | Y8: =J8/W8 -> 0.69295131 | Z8: =O8/U8 -> 0.55538318 | AA8: =K8/V8 -> 0.41242123 | AB8: =S8/M8 -> 0.011258944 | AC8: =U8/J8 -> 44.247051 | AD8: =R8/L8 -> 0.10566928 | AE8: =Q8/M8 -> 0.03792696 | AF8: =IF(B8=$AF$6,$AF$5, ) -> 3000 | AG8: =IF(E8=$AG$6,$AG$5,"") | AH8: =IF(B8=$AH$6,$AH$5,"") | AI8: =IF($B$8=AI6,AI5,"") | AJ8: =IF($B8=$AJ$6,$AJ$5,"") | AK8: =IF($B8=$AK$6,$AK$5,"") | AL8: =IF($B8=$AL$6,$AL$5,"") | AM8: =IF($B8=$AM$6,$AM$5,"") | AN8: =SUM(AF8:AM8) -> 3000 | AO8: =P8-AN8 -> -2294.9538
A9: 44563 | B9: 2 | C9: 2 | D9: 1 | E9: Sunday | F9: 1 | G9: 1 | H9: January | I9: 1 | J9: 5.6481892 | K9: =J9 -> 5.6481892 | L9: 37.00637 | M9: =K9*L9 -> 209.01898 | N9: 0.21121235 | O9: =M9*N9 -> 44.14739 | P9: =M9-O9 -> 164.87159 | Q9: 15.607485 | R9: 7.0101524 | S9: =IF(E9=$AG$6,$S$2/5,$S$2/11) -> 28.571429 | T9: 13.589794 | U9: =M9*0.7 -> 146.31329 | V9: =U9/K9 -> 25.904459 | W9: 13.883588 | X9: =Q9/V9 -> 0.60250188 | Y9: =K9/W9 -> 0.40682489 | Z9: =O9/U9 -> 0.30173193 | AA9: =K9/V9 -> 0.21803926 | AB9: =S9/M9 -> 0.13669299 | AC9: =U9/K9 -> 25.904459 | AD9: =R9/L9 -> 0.18943096 | AE9: =Q9/M9 -> 0.074670182 | AF9: =IF(B9=$AF$6,$AF$5, "") | AG9: =IF(E9=$AG$6,$AG$5,"") -> 1000 | AH9: =IF(B9=$AH$6,$AH$5,"") | AI9: =IF(B9=$AI$6,$AI$5,"") | AJ9: =IF($B9=$AJ$6,$AJ$5,"") | AK9: =IF($B9=$AK$6,$AK$5,"") | AL9: =IF($B9=$AL$6,$AL$5,"") | AM9: =IF($B9=$AM$6,$AM$5,"") | AN9: =SUM(AF9:AM9) -> 1000 | AO9: =P9-AN9 -> -835.12841
A10: 44564 | B10: 3 | C10: 3 | D10: 2 | E10: Monday | F10: 1 | G10: 1 | H10: January | I10: 1 | J10: 10.949241 | K10: =J10 -> 10.949241 | L10: 8.9188617 | M10: =K10*L10 -> 97.654762 | N10: 0.50933335 | O10: =M10*N10 -> 49.738827 | P10: =M10-O10 -> 47.915935 | Q10: 36.952446 | R10: 7.7018362 | S10: =IF(E10=$AG$6,$S$2/5,$S$2/11) -> 12.987013 | T10: 30.385295 | U10: =M10*0.7 -> 68.358333 | V10: =U10/K10 -> 6.2432032 | W10: 25.259286 | X10: =Q10/V10 -> 5.918828 | Y10: =K10/W10 -> 0.43347387 | Z10: =O10/U10 -> 0.72761907 | AA10: =K10/V10 -> 1.7537857 | AB10: =S10/M10 -> 0.13298904 | AC10: =U10/K10 -> 6.2432032 | AD10: =R10/L10 -> 0.86354475 | AE10: =Q10/M10 -> 0.37839881 | AF10: =IF(B10=$AF$6,$AF$5, "") | AG10: =IF(E10=$AG$6,$AG$5,"") | AH10: =IF(B10=$AH$6,$AH$5,"") | AI10: =IF(B10=$AI$6,$AI$5,"") | AJ10: =IF($B10=$AJ$6,$AJ$5,"") | AK10: =IF($B10=$AK$6,$AK$5,"") | AL10: =IF($B10=$AL$6,$AL$5,"") | AM10: =IF($B10=$AM$6,$AM$5,"") | AN10: =SUM(AF10:AM10) -> 0 | AO10: =P10-AN10 -> 47.915935
A11: 44565 | B11: 4 | C11: 4 | D11: 3 | E11: Tuesday | F11: 1 | G11: 1 | H11: January | I11: 1 | J11: 12.174664 | K11: =J11 -> 12.174664 | L11: 27.250856 | M11: =K11*L11 -> 331.77002 | N11: 0.36085715 | O11: =M11*N11 -> 119.72158 | P11: =M11-O11 -> 212.04843 | Q11: 26.314823 | R11: 5.9731019 | S11: =IF(E11=$AG$6,$S$2/5,$S$2/11) -> 12.987013 | T11: 25.204278 | U11: =M11*0.7 -> 232.23901 | V11: =U11/K11 -> 19.075599 | W11: 35.670771 | X11: =Q11/V11 -> 1.3795018 | Y11: =K11/W11 -> 0.34130645 | Z11: =O11/U11 -> 0.51551022 | AA11: =K11/V11 -> 0.63823233 | AB11: =S11/M11 -> 0.039144625 | AC11: =U11/K11 -> 19.075599 | AD11: =R11/L11 -> 0.21918952 | AE11: =Q11/M11 -> 0.07931646 | AF11: =IF(B11=$AF$6,$AF$5, "") | AG11: =IF(E11=$AG$6,$AG$5,"") | AH11: =IF(B11=$AH$6,$AH$5,"") | AI11: =IF(B11=$AI$6,$AI$5,"") | AJ11: =IF($B11=$AJ$6,$AJ$5,"") | AK11: =IF($B11=$AK$6,$AK$5,"") | AL11: =IF($B11=$AL$6,$AL$5,"") | AM11: =IF($B11=$AM$6,$AM$5,"") | AN11: =SUM(AF11:AM11) -> 0 | AO11: =P11-AN11 -> 212.04843
A12: 44566 | B12: 5 | C12: 5 | D12: 4 | E12: Wednesday | F12: 1 | G12: 1 | H12: January | I12: 1 | J12: 7.8061021 | K12: =J12 -> 7.8061021 | L12: 38.12985 | M12: =K12*L12 -> 297.64551 | N12: 0.34623885 | O12: =M12*N12 -> 103.05644 | P12: =M12-O12 -> 194.58907 | Q12: 32.519419 | R12: 1.4195718 | S12: =IF(E12=$AG$6,$S$2/5,$S$2/11) -> 12.987013 | T12: 27.172086 | U12: =M12*0.7 -> 208.35185 | V12: =U12/K12 -> 26.690895 | W12: 24.852601 | X12: =Q12/V12 -> 1.2183712 | Y12: =K12/W12 -> 0.31409598 | Z12: =O12/U12 -> 0.49462693 | AA12: =K12/V12 -> 0.29246311 | AB12: =S12/M12 -> 0.043632485 | AC12: =U12/K12 -> 26.690895 | AD12: =R12/L12 -> 0.037229934 | AE12: =Q12/M12 -> 0.10925553 | AF12: =IF(B12=$AF$6,$AF$5, "") | AG12: =IF(E12=$AG$6,$AG$5,"") | AH12: =IF(B12=$AH$6,$AH$5,"") | AI12: =IF(B12=$AI$6,$AI$5,"") | AJ12: =IF($B12=$AJ$6,$AJ$5,"") | AK12: =IF($B12=$AK$6,$AK$5,"") | AL12: =IF($B12=$AL$6,$AL$5,"") | AM12: =IF($B12=$AM$6,$AM$5,"") -> 1000 | AN12: =SUM(AF12:AM12) -> 1000 | AO12: =P12-AN12 -> -805.41093
A13: 44567 | B13: 6 | C13: 6 | D13: 5 | E13: Thursday | F13: 1 | G13: 1 | H13: January | I13: 1 | J13: 9.2683237 | K13: =J13 -> 9.2683237 | L13: 29.780468 | M13: =K13*L13 -> 276.01501 | N13: 0.40558507 | O13: =M13*N13 -> 111.94757 | P13: =M13-O13 -> 164.06745 | Q13: 38.666184 | R13: 8.9853593 | S13: =IF(E13=$AG$6,$S$2/5,$S$2/11) -> 12.987013 | T13: 34.524216 | U13: =M13*0.7 -> 193.21051 | V13: =U13/K13 -> 20.846327 | W13: 34.428736 | X13: =Q13/V13 -> 1.85482 | Y13: =K13/W13 -> 0.26920314 | Z13: =O13/U13 -> 0.57940724 | AA13: =K13/V13 -> 0.44460223 | AB13: =S13/M13 -> 0.047051835 | AC13: =U13/K13 -> 20.846327 | AD13: =R13/L13 -> 0.30171989 | AE13: =Q13/M13 -> 0.14008725 | AF13: =IF(B13=$AF$6,$AF$5, "") | AG13: =IF(E13=$AG$6,$AG$5,"") | AH13: =IF(B13=$AH$6,$AH$5,"") | AI13: =IF(B13=$AI$6,$AI$5,"") | AJ13: =IF($B13=$AJ$6,$AJ$5,"") | AK13: =IF($B13=$AK$6,$AK$5,"") | AL13: =IF($B13=$AL$6,$AL$5,"") | AM13: =IF($B13=$AM$6,$AM$5,"") | AN13: =SUM(AF13:AM13) -> 0 | AO13: =P13-AN13 -> 164.06745
A14: 44568 | B14: 7 | C14: 7 | D14: 6 | E14: Friday | F14: 1 | G14: 1 | H14: January | I14: 1 | J14: 5.7375578 | K14: =J14 -> 5.7375578 | L14: 43.485501 | M14: =K14*L14 -> 249.50058 | N14: 0.39389748 | O14: =M14*N14 -> 98.277649 | P14: =M14-O14 -> 151.22293 | Q14: 29.232184 | R14: 7.0897059 | S14: =IF(E14=$AG$6,$S$2/5,$S$2/11) -> 12.987013 | T14: 31.126457 | U14: =M14*0.7 -> 174.6504 | V14: =U14/K14 -> 30.439851 | W14: 35.188495 | X14: =Q14/V14 -> 0.96032612 | Y14: =K14/W14 -> 0.16305209 | Z14: =O14/U14 -> 0.56271069 | AA14: =K14/V14 -> 0.18848837 | AB14: =S14/M14 -> 0.052052036 | AC14: =U14/K14 -> 30.439851 | AD14: =R14/L14 -> 0.16303609 | AE14: =Q14/M14 -> 0.11716279 | AF14: =IF(B14=$AF$6,$AF$5, "") | AG14: =IF(E14=$AG$6,$AG$5,"") | AH14: =IF(B14=$AH$6,$AH$5,"") | AI14: =IF(B14=$AI$6,$AI$5,"") | AJ14: =IF($B14=$AJ$6,$AJ$5,"") | AK14: =IF($B14=$AK$6,$AK$5,"") | AL14: =IF($B14=$AL$6,$AL$5,"") | AM14: =IF($B14=$AM$6,$AM$5,"") | AN14: =SUM(AF14:AM14) -> 0 | AO14: =P14-AN14 -> 151.22293
A15: 44569 | B15: 8 | C15: 8 | D15: 7 | E15: Saturday | F15: 1 | G15: 1 | H15: January | I15: 1 | J15: 9.6976877 | K15: =J15 -> 9.6976877 | L15: 30.347755 | M15: =K15*L15 -> 294.30305 | N15: 0.33384866 | O15: =M15*N15 -> 98.252679 | P15: =M15-O15 -> 196.05037 | Q15: 23.267168 | R15: 2.1453246 | S15: =IF(E15=$AG$6,$S$2/5,$S$2/11) -> 12.987013 | T15: 30.204552 | U15: =M15*0.7 -> 206.01213 | V15: =U15/K15 -> 21.243428 | W15: 28.435653 | X15: =Q15/V15 -> 1.0952643 | Y15: =K15/W15 -> 0.34103973 | Z15: =O15/U15 -> 0.47692666 | AA15: =K15/V15 -> 0.45650295 | AB15: =S15/M15 -> 0.044128027 | AC15: =U15/K15 -> 21.243428 | AD15: =R15/L15 -> 0.070691378 | AE15: =Q15/M15 -> 0.079058535 | AF15: =IF(B15=$AF$6,$AF$5, "") | AG15: =IF(E15=$AG$6,$AG$5,"") | AH15: =IF(B15=$AH$6,$AH$5,"") | AI15: =IF(B15=$AI$6,$AI$5,"") | AJ15: =IF($B15=$AJ$6,$AJ$5,"") | AK15: =IF($B15=$AK$6,$AK$5,"") | AL15: =IF($B15=$AL$6,$AL$5,"") | AM15: =IF($B15=$AM$6,$AM$5,"") | AN15: =SUM(AF15:AM15) -> 0 | AO15: =P15-AN15 -> 196.05037
A16: 44570 | B16: 9 | C16: 9 | D16: 1 | E16: Sunday | F16: 2 | G16: 1 | H16: January | I16: 1 | J16: 5.5871449 | K16: =J16 -> 5.5871449 | L16: 21.60263 | M16: =K16*L16 -> 120.69702 | N16: 0.27132475 | O16: =M16*N16 -> 32.748089 | P16: =M16-O16 -> 87.948933 | Q16: 16.590911 | R16: 3.6238352 | S16: =IF(E16=$AG$6,$S$2/5,$S$2/11) -> 28.571429 | T16: 14.680302 | U16: =M16*0.7 -> 84.487915 | V16: =U16/K16 -> 15.121841 | W16: 12.701462 | X16: =Q16/V16 -> 1.0971489 | Y16: =K16/W16 -> 0.43988203 | Z16: =O16/U16 -> 0.38760678 | AA16: =K16/V16 -> 0.36947519 | AB16: =S16/M16 -> 0.23672025 | AC16: =U16/K16 -> 15.121841 | AD16: =R16/L16 -> 0.16774973 | AE16: =Q16/M16 -> 0.13745916 | AF16: =IF(B16=$AF$6,$AF$5, "") | AG16: =IF(E16=$AG$6,$AG$5,"") -> 1000 | AH16: =IF(B16=$AH$6,$AH$5,"") | AI16: =IF(B16=$AI$6,$AI$5,"") | AJ16: =IF($B16=$AJ$6,$AJ$5,"") | AK16: =IF($B16=$AK$6,$AK$5,"") | AL16: =IF($B16=$AL$6,$AL$5,"") | AM16: =IF($B16=$AM$6,$AM$5,"") | AN16: =SUM(AF16:AM16) -> 1000 | AO16: =P16-AN16 -> -912.05107
A17: 44571 | B17: 10 | C17: 10 | D17: 2 | E17: Monday | F17: 2 | G17: 1 | H17: January | I17: 1 | J17: 8.7214496 | K17: =J17 -> 8.7214496 | L17: 50.462988 | M17: =K17*L17 -> 440.11041 | N17: 0.29690507 | O17: =M17*N17 -> 130.67101 | P17: =M17-O17 -> 309.4394 | Q17: 37.40443 | R17: 7.6271942 | S17: =IF(E17=$AG$6,$S$2/5,$S$2/11) -> 12.987013 | T17: 25.73566 | U17: =M17*0.7 -> 308.07729 | V17: =U17/K17 -> 35.324092 | W17: 34.111474 | X17: =Q17/V17 -> 1.0588929 | Y17: =K17/W17 -> 0.25567496 | Z17: =O17/U17 -> 0.4241501 | AA17: =K17/V17 -> 0.24689806 | AB17: =S17/M17 -> 0.029508534 | AC17: =U17/K17 -> 35.324092 | AD17: =R17/L17 -> 0.15114432 | AE17: =Q17/M17 -> 0.084988743 | AF17: =IF(B17=$AF$6,$AF$5, "") | AG17: =IF(E17=$AG$6,$AG$5,"") | AH17: =IF(B17=$AH$6,$AH$5,"") | AI17: =IF(B17=$AI$6,$AI$5,"") -> 300 | AJ17: =IF($B17=$AJ$6,$AJ$5,"") | AK17: =IF($B17=$AK$6,$AK$5,"") | AL17: =IF($B17=$AL$6,$AL$5,"") | AM17: =IF($B17=$AM$6,$AM$5,"") | AN17: =SUM(AF17:AM17) -> 300 | AO17: =P17-AN17 -> 9.4393969
A18: 44572 | B18: 11 | C18: 11 | D18: 3 | E18: Tuesday | F18: 2 | G18: 1 | H18: January | I18: 1 | J18: 18.144643 | K18: =J18 -> 18.144643 | L18: 43.016572 | M18: =K18*L18 -> 780.52036 | N18: 0.52230161 | O18: =M18*N18 -> 407.66703 | P18: =M18-O18 -> 372.85332 | Q18: 46.794366 | R18: 9.3260607 | S18: =IF(E18=$AG$6,$S$2/5,$S$2/11) -> 12.987013 | T18: 31.99161 | U18: =M18*0.7 -> 546.36425 | V18: =U18/K18 -> 30.1116 | W18: 30.81582 | X18: =Q18/V18 -> 1.5540312 | Y18: =K18/W18 -> 0.58880936 | Z18: =O18/U18 -> 0.74614515 | AA18: =K18/V18 -> 0.60257984 | AB18: =S18/M18 -> 0.016638916 | AC18: =U18/K18 -> 30.1116 | AD18: =R18/L18 -> 0.21680158 | AE18: =Q18/M18 -> 0.059952782 | AF18: =IF(B18=$AF$6,$AF$5, "") | AG18: =IF(E18=$AG$6,$AG$5,"") | AH18: =IF(B18=$AH$6,$AH$5,"") | AI18: =IF(B18=$AI$6,$AI$5,"") | AJ18: =IF($B18=$AJ$6,$AJ$5,"") | AK18: =IF($B18=$AK$6,$AK$5,"") | AL18: =IF($B18=$AL$6,$AL$5,"") | AM18: =IF($B18=$AM$6,$AM$5,"") | AN18: =SUM(AF18:AM18) -> 0 | AO18: =P18-AN18 -> 372.85332
A19: 44573 | B19: 12 | C19: 12 | D19: 4 | E19: Wednesday | F19: 2 | G19: 1 | H19: January | I19: 1 | J19: 2.6356184 | K19: =J19 -> 2.6356184 | L19: 23.051269 | M19: =K19*L19 -> 60.754349 | N19: 0.52234832 | O19: =M19*N19 -> 31.734932 | P19: =M19-O19 -> 29.019417 | Q19: 29.957514 | R19: 3.9756458 | S19: =IF(E19=$AG$6,$S$2/5,$S$2/11) -> 12.987013 | T19: 28.772989 | U19: =M19*0.7 -> 42.528045 | V19: =U19/K19 -> 16.135889 | W19: 27.099146 | X19: =Q19/V19 -> 1.8565766 | Y19: =K19/W19 -> 0.097258354 | Z19: =O19/U19 -> 0.74621188 | AA19: =K19/V19 -> 0.1633389 | AB19: =S19/M19 -> 0.21376269 | AC19: =U19/K19 -> 16.135889 | AD19: =R19/L19 -> 0.17246971 | AE19: =Q19/M19 -> 0.4930925 | AF19: =IF(B19=$AF$6,$AF$5, "") | AG19: =IF(E19=$AG$6,$AG$5,"") | AH19: =IF(B19=$AH$6,$AH$5,"") | AI19: =IF(B19=$AI$6,$AI$5,"") | AJ19: =IF($B19=$AJ$6,$AJ$5,"") | AK19: =IF($B19=$AK$6,$AK$5,"") -> 480 | AL19: =IF($B19=$AL$6,$AL$5,"") | AM19: =IF($B19=$AM$6,$AM$5,"") | AN19: =SUM(AF19:AM19) -> 480 | AO19: =P19-AN19 -> -450.98058
A20: 44574 | B20: 13 | C20: 13 | D20: 5 | E20: Thursday | F20: 2 | G20: 1 | H20: January | I20: 1 | J20: 13.689948 | K20: =J20 -> 13.689948 | L20: 52.886584 | M20: =K20*L20 -> 724.0146 | N20: 0.45813765 | O20: =M20*N20 -> 331.69835 | P20: =M20-O20 -> 392.31625 | Q20: 30.053337 | R20: 9.9404558 | S20: =IF(E20=$AG$6,$S$2/5,$S$2/11) -> 12.987013 | T20: 25.193107 | U20: =M20*0.7 -> 506.81022 | V20: =U20/K20 -> 37.020609 | W20: 26.834492 | X20: =Q20/V20 -> 0.81180018 | Y20: =K20/W20 -> 0.51016239 | Z20: =O20/U20 -> 0.65448236 | AA20: =K20/V20 -> 0.36979263 | AB20: =S20/M20 -> 0.017937501 | AC20: =U20/K20 -> 37.020609 | AD20: =R20/L20 -> 0.18795799 | AE20: =Q20/M20 -> 0.041509297 | AF20: =IF(B20=$AF$6,$AF$5, "") | AG20: =IF(E20=$AG$6,$AG$5,"") | AH20: =IF(B20=$AH$6,$AH$5,"") | AI20: =IF(B20=$AI$6,$AI$5,"") | AJ20: =IF($B20=$AJ$6,$AJ$5,"") | AK20: =IF($B20=$AK$6,$AK$5,"") | AL20: =IF($B20=$AL$6,$AL$5,"") | AM20: =IF($B20=$AM$6,$AM$5,"") | AN20: =SUM(AF20:AM20) -> 0 | AO20: =P20-AN20 -> 392.31625
... A188: 44742 | B188: 30 | C188: 181 | D188: 5 | E188: Thursday | F188: 26 | G188: 6 | H188: June | I188: 2 | J188: 0.044856799 | K188: =J188 -> 0.044856799 | L188: 65.50402 | M188: =K188*L188 -> 2.9383007 | N188: 0.60744286 | O188: =M188*N188 -> 1.7848498 | P188: =M188-O188 -> 1.1534509 | Q188: 48.21422 | R188: 11.394534 | S188: =IF(E188=$AG$6,$S$2/5,$S$2/11) -> 12.987013 | T188: 30.836836 | U188: =M188*0.7 -> 2.0568105 | V188: =U188/K188 -> 45.852814 | W188: 31.055898 | X188: =Q188/V188 -> 1.0514997 | Y188: =K188/W188 -> 0.0014443891 | Z188: =O188/U188 -> 0.86777552 | AA188: =K188/V188 -> 0.00097827801 | AB188: =S188/M188 -> 4.4199061 | AC188: =U188/K188 -> 45.852814 | AD188: =R188/L188 -> 0.17395168 | AE188: =Q188/M188 -> 16.408879 | AF188: =IF(B188=$AF$6,$AF$5, "") | AG188: =IF(E188=$AG$6,$AG$5,"") | AH188: =IF(B188=$AH$6,$AH$5,"") | AI188: =IF(B188=$AI$6,$AI$5,"") | AJ188: =IF($B188=$AJ$6,$AJ$5,"") | AK188: =IF($B188=$AK$6,$AK$5,"") | AL188: =IF($B188=$AL$6,$AL$5,"") | AM188: =IF($B188=$AM$6,$AM$5,"") | AN188: =SUM(AF188:AM188) -> 0 | AO188: =P188-AN188 -> 1.1534509
A189: 44743 | B189: 1 | C189: 182 | D189: 6 | E189: Friday | F189: 26 | G189: 7 | H189: July | I189: 3 | J189: 4.0545139 | K189: =J189-(J189*0.4) -> 2.4327083 | L189: 105.67501 | M189: =K189*L189 -> 257.07647 | N189: 0.80253747 | O189: =M189*N189 -> 206.3135 | P189: =M189-O189 -> 50.762971 | Q189: 40.641381 | R189: 9.2642994 | S189: =IF(E189=$AG$6,$S$2/5,$S$2/11) -> 12.987013 | T189: 34.414125 | U189: =M189*0.7 -> 179.95353 | V189: =U189/K189 -> 73.972505 | W189: 33.975664 | X189: =Q189/V189 -> 0.549412 | Y189: =K189/W189 -> 0.071601495 | Z189: =O189/U189 -> 1.1464821 | AA189: =K189/V189 -> 0.032886657 | AB189: =S189/M189 -> 0.050518093 | AC189: =U189/K189 -> 73.972505 | AD189: =R189/L189 -> 0.087667838 | AE189: =Q189/M189 -> 0.15809063 | AF189: =IF(B189=$AF$6,$AF$5, "") -> 3000 | AG189: =IF(E189=$AG$6,$AG$4,"") | AH189: =IF(B189=$AH$6,$AH$5,"") | AI189: =IF(B189=$AI$6,$AI$5,"") | AJ189: =IF($B189=$AJ$6,$AJ$5,"") | AK189: =IF($B189=$AK$6,$AK$5,"") | AL189: =IF($B189=$AL$6,$AL$5,"") | AM189: =IF($B189=$AM$6,$AM$5,"") | AN189: =SUM(AF189:AM189) -> 3000 | AO189: =P189-AN189 -> -2949.237
